<?xml version="1.0"?>
<robot name="wheeled_bot"  xlmns:xacro="http://www.ros.org/wiki/xacro">
	<material name="blue">
		<color rgba="0 0 1 1"/>
	</material>
	<material name="red">
		<color rgba="0 1 0 1"/>
	</material>
	<link name="base_link">
		<visual>
		<geometry>
			<box size="0.5 1 0.1"/>
		</geometry>
		<material name="blue"/>
		</visual>
		<collision>
		<geometry>
			<box size="0.5 1 0.1"/>
		</geometry>
		<material name="blue"/>
		</collision>
		
	</link>
	
	<link name="forewheel1_link">
		<visual>
		<geometry>
			<cylinder length="0.2" radius="0.2"/>
		</geometry>
		<material name="red"/>
		<origin xyz="-0.25 -0.6 0" rpy="1.57 1.57 0" />
		</visual>
		<collision>
		<geometry>
			<cylinder length="0.2" radius="0.2"/>
		</geometry>
		<material name="red"/>
		<origin xyz="-0.25 -0.6 0" rpy="1.57 1.57 0" />
		</collision>
		<inertial>
			<mass value="10"/>
			<inertia ixx="0.1333" ixy="0.0" ixz="0.0" iyy="0.1333" iyz="0.0" izz="0.2"/>
		</inertial>
	</link>
	
	<link name="forewheel2_link">
		<visual>
		<geometry>
			<cylinder length="0.2" radius="0.2"/>
		</geometry>
		<material name="red"/>
		<origin xyz="0.25 -0.6 0" rpy="1.57 1.57 0" />
		</visual>
		<collision>
		<geometry>
			<cylinder length="0.2" radius="0.2"/>
		</geometry>
		<material name="red"/>
		<origin xyz="0.25 -0.6 0" rpy="1.57 1.57 0" />
		</collision>
		<inertial>
			<mass value="10"/>
			<inertia ixx="0.1333" ixy="0.0" ixz="0.0" iyy="0.1333" iyz="0.0" izz="0.2"/>
		</inertial>
	</link>

	<link name="backwheel1_link">
		<visual>
		<geometry>
			<cylinder length="0.2" radius="0.2"/>
		</geometry>
		<material name="red"/>
		<origin xyz="0.25 0.6 0" rpy="1.57 1.57 0" />
		</visual>
		<collision>
		<geometry>
			<cylinder length="0.2" radius="0.2"/>
		</geometry>
		<material name="red"/>
		<origin xyz="0.25 0.6 0" rpy="1.57 1.57 0" />
		</collision>
		<inertial>
			<mass value="10"/>
			<inertia ixx="0.1333" ixy="0.0" ixz="0.0" iyy="0.1333" iyz="0.0" izz="0.2"/>
		</inertial>
	</link>

	<link name="backwheel2_link">
		<visual>
		<geometry>
			<cylinder length="0.2" radius="0.2"/>
		</geometry>
		<material name="red"/>
		<origin xyz="-0.25 0.6 0" rpy="1.57 1.57 0" />
		</visual>
		<collision>
		<geometry>
			<cylinder length="0.2" radius="0.2"/>
		</geometry>
		<material name="red"/>
		<origin xyz="-0.25 0.6 0" rpy="1.57 1.57 0" />
		</collision>
		<inertial>
			<mass value="10"/>
			<inertia ixx="0.1333" ixy="0.0" ixz="0.0" iyy="0.1333" iyz="0.0" izz="0.2"/>
		</inertial>
	</link>

	<joint name="basetof1" type="continuous">
		<parent link="base_link"/>
		<child link="forewheel1_link"/>
		<axis xyz="1 0 0"/>
		<origin xyz="0 0 -0.08"/>
	</joint>
	<joint name="basetof2" type="fixed">
		<parent link="base_link"/>
		<child link="forewheel2_link"/>
		<axis xyz="1 0 0"/>
		<origin xyz="0 0 -0.08"/>
	</joint>
	<joint name="basetor1" type="fixed">
		<parent link="base_link"/>
		<child link="backwheel1_link"/>
		<axis xyz="1 0 0"/>
		<origin xyz="0 0 -0.08"/>
	</joint>
	<joint name="basetor2" type="fixed">
		<parent link="base_link"/>
		<child link="backwheel2_link"/>
		<axis xyz="1 0 0"/>
		<origin xyz="0 0 -0.08"/>
	</joint>
</robot>
<gazebo>
	<plugin name="gazebo_ros_control" filename="libgazebo_ros_control.so">
	<robotNamespace>/</robotNamespace>
	</plugin>
</gazebo>



<robot name="wheeled_bot">
	<material name="blue">
		<color rgba="0 0 1 1"/>
	</material>
	<material name="red">
		<color rgba="1 0 0 1"/>
	</material>
	<link name="base_link">
		<visual>
		<geometry>
			<box size="0.5 1 0.1"/>
		</geometry>
		<material name="blue"/>
		</visual>
		<collision>
		<geometry>
			<box size="0.5 1 0.1"/>
		</geometry>
		<material name="blue"/>
		</collision>
		<inertial>
			<mass value="10"/>
			<inertia ixx="0.84167" ixy="0.0" ixz="0.0" iyy="0.2167" iyz="0.0" izz="1.04167"/>
		</inertial>
	</link>
	<link name="support1">
		<visual>
		<geometry>
			<cylinder length="1.2" radius="0.02"/>
		</geometry>
		<origin xyz="-0.25 0 0" rpy="1.57 0 0"/>
		</visual>
		<collision>
		<geometry>
			<cylinder length="1.2" radius="0.02"/>
		</geometry>
		<origin xyz="-0.25 0 0" rpy="1.57 0 0"/>			
		</collision>
	</link>
	
	<link name="support2">
		<visual>
		<geometry>
			<cylinder length="1.2" radius="0.02"/>
		</geometry>
		<origin xyz="0.25 0 0" rpy="1.57 0 0"/>
		</visual>
		<collision>
		<geometry>
			<cylinder length="1.2" radius="0.02"/>
		</geometry>
		<origin xyz="0.25 0 0" rpy="1.57 0 0"/>			
		</collision>
	</link>		
	
	<link name="forewheel1_link">
		<visual>
		<geometry>
			<cylinder length="0.2" radius="0.2"/>
		</geometry>
		<material name="red"/>
		<origin xyz="-0.25 -0.6 0" rpy="1.57 1.57 0" />
		</visual>
		<collision>
		<geometry>
			<cylinder length="0.2" radius="0.2"/>
		</geometry>
		<material name="red"/>
		<origin xyz="-0.25 -0.6 0" rpy="1.57 1.57 0" />
		</collision>
		<inertial>
			<mass value="10"/>
			<inertia ixx="0.1333" ixy="0.0" ixz="0.0" iyy="0.1333" iyz="0.0" izz="0.2"/>
		</inertial>
	</link>
	
	<link name="forewheel2_link">
		<visual>
		<geometry>
			<cylinder length="0.2" radius="0.2"/>
		</geometry>
		<material name="red"/>
		<origin xyz="0.25 -0.6 0" rpy="1.57 1.57 0" />
		</visual>
		<collision>
		<geometry>
			<cylinder length="0.2" radius="0.2"/>
		</geometry>
		<material name="red"/>
		<origin xyz="0.25 -0.6 0" rpy="1.57 1.57 0" />
		</collision>
		<inertial>
			<mass value="10"/>
			<inertia ixx="0.1333" ixy="0.0" ixz="0.0" iyy="0.1333" iyz="0.0" izz="0.2"/>
		</inertial>
	</link>

	<link name="backwheel1_link">
		<visual>
		<geometry>
			<cylinder length="0.2" radius="0.2"/>
		</geometry>
		<material name="red"/>
		<origin xyz="0.25 0.6 0" rpy="1.57 1.57 0" />
		</visual>
		<collision>
		<geometry>
			<cylinder length="0.2" radius="0.2"/>
		</geometry>
		<material name="red"/>
		<origin xyz="0.25 0.6 0" rpy="1.57 1.57 0" />
		</collision>
		<inertial>
			<mass value="10"/>
			<inertia ixx="0.1333" ixy="0.0" ixz="0.0" iyy="0.1333" iyz="0.0" izz="0.2"/>
		</inertial>
	</link>

	<link name="backwheel2_link">
		<visual>
		<geometry>
			<cylinder length="0.2" radius="0.2"/>
		</geometry>
		<material name="red"/>
		<origin xyz="-0.25 0.6 0" rpy="1.57 1.57 0" />
		</visual>
		<collision>
		<geometry>
			<cylinder length="0.2" radius="0.2"/>
		</geometry>
		<material name="red"/>
		<origin xyz="-0.25 0.6 0" rpy="1.57 1.57 0" />
		</collision>
		<inertial>
			<mass value="10"/>
			<inertia ixx="0.1333" ixy="0.0" ixz="0.0" iyy="0.1333" iyz="0.0" izz="0.2"/>
		</inertial>
	</link>

	<joint name="link_basetowheel" type="fixed">
		<parent link="base_link"/>
		<child link="support1"/>
		<!--child link="forewheel2_link"/-->
	</joint>
	
	<joint name="link_basetowheel1" type="fixed">
		<parent link="base_link"/>
		<child link="support2"/>
		<!--child link="backwheel2_link"/-->
	</joint>

	<joint name="basetof1" type="continuous">
		<parent link="support1"/>
		<child link="forewheel1_link"/>
		<!--limit effort="1000.0"  velocity="0.5"/-->
		<axis xyz="0 0 1"/>
		<origin xyz="0 0 -0.08" rpy="1.57075  0  0"/>
	</joint>
	<joint name="basetof2" type="continuous">
		<parent link="support1"/>
		<child link="forewheel2_link"/>
		<axis xyz="0 0 1"/>
		<!--limit effort="1000.0" lower="0.0" upper="0.548" velocity="0.5"/-->
		<origin xyz="0 0 -0.08" rpy="1.57075  0  0"/>
	</joint>
	<joint name="basetor1" type="continuous">
		<parent link="support2"/>
		<child link="backwheel1_link"/>
		<axis xyz="0 0 1"/>
		<!--limit effort="1000.0" lower="0.0" upper="0.548" velocity="0.5"/-->
		<origin xyz="0 0 -0.08" rpy="1.57075  0  0"/>
	</joint>
	<joint name="basetor2" type="continuous">
		<parent link="support2"/>
		<child link="backwheel2_link"/>
		<axis xyz="0 0 1"/>
		<!--limit effort="1000.0" lower="0.0" upper="0.548" velocity="0.5"/-->
		<origin xyz="0 0 -0.08" rpy="1.57075  0  0"/>
	</joint>
</robot>
